<?xml version="0.0" ?>
<robot name="quadruped">

<link name="torso">
<contact>
  <lateral_friction value="1.0"/>
  <inertia_scaling value="3.0"/>
</contact>
<inertial>
  <mass value="0.3"/>
  <inertia ixx="1" ixy="0" ixz="0" iyy="1" iyz="0" izz="1"/>
</inertial>
<collision>
  <origin xyz="0 0 0" rpy="0 0 0"/>
  <geometry>
  <box size="0.3 0.2 0.1"/>
  </geometry>
</collision>
</link>

<link name="frlp">
<contact>
  <lateral_friction value="1.0"/>
  <inertia_scaling value="3.0"/>
</contact>
<inertial>
  <mass value="0.2"/>
  <inertia ixx="1" ixy="0" ixz="0" iyy="1" iyz="0" izz="1"/>
</inertial>
<collision>
  <origin xyz="0.13 -0.08 -0.10500000000000001" rpy="0 0 0"/>
  <geometry>
  <capsule length="0.05" radius="0.02"/>
  </geometry>
</collision>
</link>

<link name="frld">
<contact>
  <lateral_friction value="1.0"/>
  <inertia_scaling value="3.0"/>
</contact>
<inertial>
  <mass value="0.2"/>
  <inertia ixx="1" ixy="0" ixz="0" iyy="1" iyz="0" izz="1"/>
</inertial>
<collision>
  <origin xyz="0 0 -0.08" rpy="0 0 0"/>
  <geometry>
  <capsule length="0.02" radius="0.02"/>
  </geometry>
</collision>
</link>

<link name="fllp">
<contact>
  <lateral_friction value="1.0"/>
  <inertia_scaling value="3.0"/>
</contact>
<inertial>
  <mass value="0.2"/>
  <inertia ixx="1" ixy="0" ixz="0" iyy="1" iyz="0" izz="1"/>
</inertial>
<collision>
  <origin xyz="0.13 0.08 -0.10500000000000001" rpy="0 0 0"/>
  <geometry>
  <capsule length="0.05" radius="0.02"/>
  </geometry>
</collision>
</link>

<link name="flld">
<contact>
  <lateral_friction value="1.0"/>
  <inertia_scaling value="3.0"/>
</contact>
<inertial>
  <mass value="0.2"/>
  <inertia ixx="1" ixy="0" ixz="0" iyy="1" iyz="0" izz="1"/>
</inertial>
<collision>
  <origin xyz="0 0 -0.08" rpy="0 0 0"/>
  <geometry>
  <capsule length="0.02" radius="0.02"/>
  </geometry>
</collision>
</link>

<link name="hrlp">
<contact>
  <lateral_friction value="1.0"/>
  <inertia_scaling value="3.0"/>
</contact>
<inertial>
  <mass value="0.2"/>
  <inertia ixx="1" ixy="0" ixz="0" iyy="1" iyz="0" izz="1"/>
</inertial>
<collision>
  <origin xyz="-0.13 -0.08 -0.10500000000000001" rpy="0 0 0"/>
  <geometry>
  <capsule length="0.05" radius="0.02"/>
  </geometry>
</collision>
</link>

<link name="hrld">
<contact>
  <lateral_friction value="1.0"/>
  <inertia_scaling value="3.0"/>
</contact>
<inertial>
  <mass value="0.2"/>
  <inertia ixx="1" ixy="0" ixz="0" iyy="1" iyz="0" izz="1"/>
</inertial>
<collision>
  <origin xyz="0 0 -0.08" rpy="0 0 0"/>
  <geometry>
  <capsule length="0.02" radius="0.02"/>
  </geometry>
</collision>
</link>

<link name="hllp">
<contact>
  <lateral_friction value="1.0"/>
  <inertia_scaling value="3.0"/>
</contact>
<inertial>
  <mass value="0.2"/>
  <inertia ixx="1" ixy="0" ixz="0" iyy="1" iyz="0" izz="1"/>
</inertial>
<collision>
  <origin xyz="-0.13 0.08 -0.10500000000000001" rpy="0 0 0"/>
  <geometry>
  <capsule length="0.05" radius="0.02"/>
  </geometry>
</collision>
</link>

<link name="hlld">
<contact>
  <lateral_friction value="1.0"/>
  <inertia_scaling value="3.0"/>
</contact>
<inertial>
  <mass value="0.2"/>
  <inertia ixx="1" ixy="0" ixz="0" iyy="1" iyz="0" izz="1"/>
</inertial>
<collision>
  <origin xyz="0 0 -0.08" rpy="0 0 0"/>
  <geometry>
  <capsule length="0.02" radius="0.02"/>
  </geometry>
</collision>
</link>

<joint name="tfrlp" type="continuous">
  <parent link="torso"/>
  <child link="frlp"/>
  <origin xyz="0 0 0" rpy="0 0 0"/>
  <axis xyz="0 1 0"/>
</joint>

<joint name="tfrld" type="continuous">
  <parent link="frlp"/>
  <child link="frld"/>
  <origin xyz="0.13 -0.08 -0.10500000000000001" rpy="0 0 0"/>
  <axis xyz="0 1 0"/>
</joint>

<joint name="tfllp" type="continuous">
  <parent link="torso"/>
  <child link="fllp"/>
  <origin xyz="0 0 0" rpy="0 0 0"/>
  <axis xyz="0 1 0"/>
</joint>

<joint name="tflld" type="continuous">
  <parent link="fllp"/>
  <child link="flld"/>
  <origin xyz="0.13 0.08 -0.10500000000000001" rpy="0 0 0"/>
  <axis xyz="0 1 0"/>
</joint>

<joint name="thrlp" type="continuous">
  <parent link="torso"/>
  <child link="hrlp"/>
  <origin xyz="0 0 0" rpy="0 0 0"/>
  <axis xyz="0 1 0"/>
</joint>

<joint name="thrld" type="continuous">
  <parent link="hrlp"/>
  <child link="hrld"/>
  <origin xyz="-0.13 -0.08 -0.10500000000000001" rpy="0 0 0"/>
  <axis xyz="0 1 0"/>
</joint>

<joint name="thllp" type="continuous">
  <parent link="torso"/>
  <child link="hllp"/>
  <origin xyz="0 0 0" rpy="0 0 0"/>
  <axis xyz="0 1 0"/>
</joint>

<joint name="thlld" type="continuous">
  <parent link="hllp"/>
  <child link="hlld"/>
  <origin xyz="-0.13 0.08 -0.10500000000000001" rpy="0 0 0"/>
  <axis xyz="0 1 0"/>
</joint>

</robot>
